<?xml version="1.0" encoding="utf-8"?>
<!-- This URDF was automatically created by SolidWorks to URDF Exporter! Originally created by Stephen Brawner (brawner@gmail.com)
     Commit Version: 1.5.1-0-g916b5db  Build Version: 1.5.7152.31018
     For more information, please see http://wiki.ros.org/sw_urdf_exporter -->
<robot
  name="cart_pole_3d">

  <link
    name="base_link">
    <inertial>
      <origin
        xyz="0 0.016588 -7.0567E-17"
        rpy="0 0 0" />
      <mass
        value="10.2" />
      <inertia
        ixx="0.057887"
        ixy="-2.0329E-17"
        ixz="9.6317E-18"
        iyy="3.4542"
        iyz="-3.7197E-18"
        izz="3.4037" />
    </inertial>
    <visual>
      <origin
        xyz="0 0 0"
        rpy="0 0 0" />
      <geometry>
        <mesh
          filename="package://cart_pole_3d_description/meshes/base_link.STL" />
      </geometry>
      <material
        name="White">
        <color
          rgba="1 1 1 1" />
      </material>
    </visual>
    <collision>
      <origin
        xyz="0 0 0"
        rpy="0 0 0" />
      <geometry>
        <mesh
          filename="package://cart_pole_3d_description/meshes/base_link.STL" />
      </geometry>
    </collision>
  </link>

  <gazebo reference="base_Link">
      <kp>1000</kp>
      <kd>1000</kd>
      <mu1>0.5</mu1>
      <mu2>0.5</mu2>
      <material>Gazebo/White</material>
  </gazebo>

  <!-- Used for fixing robot to Gazebo 'base_link' -->
 <link name="world"/>
 <joint name="fixed" type="fixed">
   <parent link="world"/>
   <child link="base_link"/>
 </joint>

  <link
    name="cart_Link">
    <inertial>
      <origin
        xyz="8.7244E-18 -1.0887E-07 0.004059"
        rpy="0 0 0" />
      <mass
        value="13.204" />
      <inertia
        ixx="0.10629"
        ixy="8.1278E-08"
        ixz="-2.9575E-18"
        iyy="0.17178"
        iyz="4.5022E-07"
        izz="0.2371" />
    </inertial>
    <visual>
      <origin
        xyz="0 0 0"
        rpy="0 0 0" />
      <geometry>
        <mesh
          filename="package://cart_pole_3d_description/meshes/cart_Link.STL" />
      </geometry>
      <material
        name="Red">
        <color
          rgba="1 0 0 1" />
      </material>
    </visual>
    <collision>
      <origin
        xyz="0 0 0"
        rpy="0 0 0" />
      <geometry>
        <mesh
          filename="package://cart_pole_3d_description/meshes/cart_Link.STL" />
      </geometry>
    </collision>
  </link>

  <joint
    name="base_cart_joint"
    type="prismatic">
    <origin
      xyz="0 0 0.072"
      rpy="0 0 0" />
    <parent
      link="base_link" />
    <child
      link="cart_Link" />
    <axis
      xyz="1 0 0" />
    <limit
      lower= "-2"
      upper="2"
      effort="2000000"
      velocity="100000" />
  </joint>

  <gazebo reference="cart_Link">
      <kp>1000</kp>
      <kd>1000</kd>
      <mu1>0.5</mu1>
      <mu2>0.5</mu2>
      <material>Gazebo/Red</material>
  </gazebo>

  <link
    name="pole_Link">
    <inertial>
      <origin
        xyz="4.3315E-18 1.3127E-16 0.29235"
        rpy="0 0 0" />
      <mass
        value="0.83758" />
      <inertia
        ixx="0.022017"
        ixy="1.6996E-20"
        ixz="-3.6264E-19"
        iyy="0.022127"
        iyz="-1.0739E-17"
        izz="0.00023906" />
    </inertial>
    <visual>
      <origin
        xyz="0 0 0"
        rpy="0 0 0" />
      <geometry>
        <mesh
          filename="package://cart_pole_3d_description/meshes/pole_Link.STL" />
      </geometry>
      <material
        name="Blue">
        <color
          rgba="0 0 1 1" />
      </material>
    </visual>
    <collision>
      <origin
        xyz="0 0 0"
        rpy="0 0 0" />
      <geometry>
        <mesh
          filename="package://cart_pole_3d_description/meshes/pole_Link.STL" />
      </geometry>
    </collision>
  </link>

  <gazebo reference="pole_Link">
      <kp>1000.0</kp>
      <kd>1000.0</kd>
      <mu1>0.5</mu1>
      <mu2>0.5</mu2>
      <material>Gazebo/Blue</material>
  </gazebo>

  <joint name="cart_pole_joint" type="revolute">
    <origin
      xyz="0 0 0.1305"
      rpy="0 0 0" />
    <parent link="cart_Link" />
    <child link="pole_Link" />
    <axis xyz="0 -1 0" />
    <limit
      lower="-1"
      upper="1"
      effort="1"
      velocity="100" />
  </joint>
  <!-- <link
    name="top_weight_Link">
    <inertial>
      <origin
        xyz="5.0699E-18 0 -0.00030865"
        rpy="0 0 0" />
      <mass
        value="0.3739" />
      <inertia
        ixx="0.00029872"
        ixy="0"
        ixz="0"
        iyy="0.00029872"
        iyz="0"
        izz="0.00029872" />
    </inertial>
    <visual>
      <origin
        xyz="0 0 0"
        rpy="0 0 0" />
      <geometry>
        <mesh
          filename="package://cart_pole_3d_description/meshes/top_weight_Link.STL" />
      </geometry>
      <material
        name="Green">
        <color
          rgba="0 1 0 1" />
      </material>
    </visual>
    <collision>
      <origin
        xyz="0 0 0"
        rpy="0 0 0" />
      <geometry>
        <mesh
          filename="package://cart_pole_3d_description/meshes/top_weight_Link.STL" />
      </geometry>
    </collision>
  </link>

  <gazebo reference="top_weight_Link">
      <kp>10</kp>
      <kd>10.0</kd>
      <mu1>1</mu1>
      <mu2>1</mu2>
      <material>Gazebo/Green</material>
  </gazebo>

  <joint
    name="pole_ball_joint"
    type="fixed">
    <origin
      xyz="0 0 0.61694"
      rpy="0 0 0" />
    <parent
      link="pole_Link" />
    <child
      link="top_weight_Link" />
    <axis
      xyz="0 0 0" />
  </joint> -->


  <gazebo>
  <plugin name="p3d_base_controller" filename="libgazebo_ros_p3d.so">
      <robotNamespace>/cart_pole_3d</robotNamespace>
      <alwaysOn>true</alwaysOn>
      <updateRate>50.0</updateRate>
      <bodyName>cart_Link</bodyName>
      <topicName>odom</topicName>
      <gaussianNoise>0.01</gaussianNoise>
      <frameName>world</frameName>
      <xyzOffsets>0 0 0</xyzOffsets>
      <rpyOffsets>0 0 0</rpyOffsets>
  </plugin>
</gazebo>

  <gazebo>
    <plugin name="imu_plugin" filename="libgazebo_ros_imu.so">
      <robotNamespace>/cart_pole_3d</robotNamespace>
        <alwaysOn>true</alwaysOn>
        <bodyName>pole_Link</bodyName>
        <topicName>imu</topicName>
        <serviceName>imu_service</serviceName>
        <gaussianNoise>0.8</gaussianNoise>
        <updateRate>50.0</updateRate>
    </plugin>
  </gazebo>

  <gazebo>
  <plugin name="gazebo_ros_control" filename="libgazebo_ros_control.so">
      <robotNamespace>/cart_pole_3d</robotNamespace>
  </plugin>
  </gazebo>

  <transmission name="cart_pole_joint_transmission">
    <type>transmission_interface/SimpleTransmission</type>
    <joint name="cart_pole_joint">
      <hardwareInterface>hardware_interface/EffortJointInterface</hardwareInterface>
    </joint>
    <actuator name="cart_pole_joint_motor">
      <hardwareInterface>hardware_interface/EffortJointInterface</hardwareInterface>
      <mechanicalReduction>1</mechanicalReduction>
    </actuator>
  </transmission>

  <transmission name="linear_cart_joint_transmission">
    <type>transmission_interface/SimpleTransmission</type>
    <joint name="base_cart_joint">
      <hardwareInterface>hardware_interface/EffortJointInterface</hardwareInterface>
    </joint>
    <actuator name="linear_cart_joint_motor">
      <hardwareInterface>hardware_interface/EffortJointInterface</hardwareInterface>
      <mechanicalReduction>1</mechanicalReduction>
    </actuator>
  </transmission>



</robot>
